Workbook

Sheet Deckblatt
B2: EOP / Microsoft Defender for Office 365
B3: Assessment- und Umsetzungs-Checkliste
B4: Wiederverwendbarer Hardening-Standard · Recherchestand August 2026
B6: Projektangaben
B7: Kunde | C7: <Kundenname eintragen>
B8: Tenant / Primärdomäne | C8: <kunde.onmicrosoft.com>
B9: Weitere Maildomänen | C9: <domain1.de, domain2.de>
B10: Datum der Aufnahme | C10: <TT.MM.JJJJ>
B11: Durchgeführt von | C11: <Name>
B12: Lizenzstand (EOP / MDO P1 / MDO P2 / E5) | C12: <z. B. M365 E3 + MDO P1>
B13: MX-Ziel (zeigt direkt auf EXO?) | C13: <ja / nein — falls nein: welches Gateway?>
B14: Hybrid mit On-Prem Exchange? | C14: <ja / nein — falls ja: Version>
B15: Preset-Nutzung im Ist-Zustand | C15: <keines / Standard / Strict / Custom>
B17: So wird die Liste benutzt
B18: 1. | C18: Auf dem Blatt „Checkliste“ nur die gelb hinterlegten Spalten ausfüllen: Ist-Wert, Bewertung, Notizen.
B19: 2. | C19: Die Spalte „Prüfung (PowerShell)“ liefert den Befehl, der den Ist-Wert ausliest. Alternativ das Skript Invoke-EopAudit.ps1 laufen lassen — es füllt die Ist-Werte automatisch als CSV.
B20: 3. | C20: „Bewertung“ ist eine Auswahlliste. „bewusst abgewichen“ ist ein legitimes Ergebnis — dann bitte die Begründung in „Notizen“ festhalten.
B21: 4. | C21: Die Spalten MS Default / Standard / Strict zeigen, was Microsoft an dieser Stelle vorgibt. Sie sind die Argumentationsgrundlage gegenüber dem Kunden.
B22: 5. | C22: Das Blatt „Auswertung“ zählt automatisch mit und ist die Basis für die Abschlussbesprechung.
B23: 6. | C23: Ausführliche Begründungen zu jedem Prüfpunkt stehen im Begleitdokument „EOP-MDO Best Practice Guide“ — dort ist dieselbe ID verwendet.
B25: Bedeutung der Bewertungen
B26: OK | C26: Ist-Wert entspricht dem Soll. Keine Maßnahme.
B27: Verbesserung empfohlen | C27: Abweichung ohne akutes Risiko. Einplanen, nicht dringend.
B28: Kritisch | C28: Schutzwirkung fehlt oder ist wirkungslos. Sofort adressieren.
B29: n.a. (nicht lizenziert) | C29: Feature im Tenant nicht verfügbar. Als Lizenzargument notieren.
B30: bewusst abgewichen | C30: Abweichung ist gewollt und begründet. Begründung gehört in „Notizen“.
B31: offen | C31: Noch nicht geprüft.
B33: Hinweis zur Verwendung
B34: Alle Cmdlets und Parameter wurden gegen die Microsoft-Learn-Referenz (Stand August 2026) verifiziert. Sie wurden jedoch NICHT gegen einen Produktivtenant getestet. Vor der Umsetzung immer erst das Audit-Skript im Lesemodus laufen lassen und das Hardening-Skript mit -WhatIf.

Sheet Checkliste
A1: ID | B1: Kategorie | C1: Prüfpunkt | D1: Ist-Wert beim Kunden | E1: Bewertung | F1: Soll 2026 (Baseline) | G1: Bisherige Empfehlung (2023) | H1: MS Default | I1: MS Standard-Preset | J1: MS Strict-Preset | K1: Lizenz | L1: Prüfung (PowerShell) | M1: Umsetzung (PowerShell) | N1: Fundort (Klickpfad im Portal) | O1: Portal öffnen | P1: Microsoft Learn | Q1: Hinweise, Fallstricke, Abweichungen | R1: Notizen / Ticket
A2: BEISPIEL | B2: — Beispielzeile, bitte löschen — | C2: So sieht eine ausgefüllte Zeile aus | D2: BulkThreshold = 7 | E2: Verbesserung empfohlen | F2: 6 | G2: 6 statt 7 | H2: 7 | I2: 6 | J2: 5 | K2: EOP | L2: Get-HostedContentFilterPolicy | ft Name,BulkThreshold | M2: Set-HostedContentFilterPolicy -Identity "Default" -BulkThreshold 6 | N2: Defender-Portal > Bedrohungsrichtlinien > Antispam > <Richtlinie> > "Massen-E-Mail-Schwellenwert & Spameigenschaften" | O2: Portal | P2: Learn | Q2: Mit dem Kunden am 12.08. besprochen, Umsetzung im Wartungsfenster. | R2: TICKET-4711
A3: Preset Security Policies
A4: PRE-01 | B4: Preset Security Policies | C4: Grundsatzentscheidung: Preset (Standard/Strict) vs. Custom-Policies | E4: offen | F4: Bewusste, dokumentierte Entscheidung. Empfehlung 2026: Custom-Policies auf Standard-Preset-Niveau, wo Kontrolle nötig ist (ASF, Quarantäne-Policies, Länderfilter) — sonst Standard-Preset. | G4: Default/Custom bevorzugt, weil dort alles von Hand vorgegeben werden kann. Standard nur, wenn keine Zeit. Hinweis: MS behält sich bei Standard/Strict Anpassungen vor. | H4: Standard/Strict sind ab Werk NICHT zugewiesen | I4: muss aktiviert werden | J4: muss aktiviert werden | K4: EOP (EOP-Teil) / MDO P1+ (MDO-Teil) | L4: Get-EOPProtectionPolicyRule | Format-Table Name,State Get-ATPProtectionPolicyRule | Format-Table Name,State | M4: Enable-EOPProtectionPolicyRule -Identity "Standard Preset Security Policy" Enable-ATPProtectionPolicyRule -Identity "Standard Preset Security Policy" | N4: Defender-Portal > Bedrohungsrichtlinien > Voreingestellte Sicherheitsrichtlinien (Preset security policies) | O4: Portal öffnen | P4: Learn | Q4: EOP-Teil und MDO-Teil des Presets werden GETRENNT aktiviert - ein Preset kann halb aktiv sein. Empfänger in Standard/Strict ignorieren alle Custom-Policy-Einstellungen (kein Merging).
A5: PRE-02 | B5: Preset Security Policies | C5: Built-in protection Preset (Safe Links / Safe Attachments) aktiv, keine pauschalen Ausnahmen | E5: offen | F5: Aktiv, keine Ausnahmen für ganze Domänen | G5: — | H5: allen Empfängern zugewiesen (default-on) | I5: n.a. | J5: n.a. | K5: MDO P1/P2 | L5: Get-ATPBuiltInProtectionRule | Format-List Name,State,ExceptIfRecipientDomainIs,ExceptIfSentTo,ExceptIfSentToMemberOf | M5: Set-ATPBuiltInProtectionRule -Identity "ATP Built-In Protection Rule" -ExceptIfRecipientDomainIs $null -ExceptIfSentTo $null -ExceptIfSentToMemberOf $null | N5: Defender-Portal > Bedrohungsrichtlinien > Voreingestellte Sicherheitsrichtlinien > Integrierter Schutz (Built-in protection) > "Ausschluesse verwalten" | O5: Portal öffnen | P5: Learn | Q5: Built-in ist SCHWÄCHER als Standard/Strict (AllowClickThrough=$true, EnableForInternalSenders=$false) und deckt nur Safe Links/Safe Attachments ab. Kein Ersatz für Standard/Strict. Häufiges Anti-Pattern: alle Accepted Domains ausgeschlossen.
A6: PRE-03 | B6: Preset Security Policies | C6: Policy-Präzedenz dokumentiert und geprüft (welche Policy greift je Empfänger?) | E6: offen | F6: Kette dokumentiert: Strict > Standard > MDO-Evaluation > Custom (nach Priority) > Built-in + Default (gleichrangig) | G6: — | H6: — | I6: — | J6: — | K6: EOP | L6: Get-HostedContentFilterRule | Format-Table Name,Priority,State,SentTo,RecipientDomainIs Get-AntiPhishRule | Format-Table Name,Priority,State Get-MalwareFilterRule | Format-Table Name,Priority,State | M6: Set-HostedContentFilterRule -Identity "<Rule>" -Priority 0 | N6: Kein eigener Portal-Screen. Praezedenz ablesen an der Spalte "Prioritaet" je Richtlinientyp (Antispam, Antiphishing, ...) plus der Preset-Seite | O6: Portal öffnen | P6: Learn | Q6: Pro Empfänger greift genau EINE Policy je Typ - es gibt kein Merging. Verdict-Reihenfolge separat: Malware > HC-Phish > Phish > HC-Spam > Spoof > Impersonation > Spam > Bulk.
A7: PRE-04 | B7: Preset Security Policies | C7: Configuration Analyzer ausgewertet (Standard- und Strict-Empfehlungen) | E7: offen | F7: Vor und nach dem Hardening ausgeführt, Abweichungen dokumentiert | G7: Configuration Analyzer nutzen | H7: — | I7: — | J7: — | K7: EOP / MDO | L7: Get-ConfigAnalyzerPolicyRecommendation -RecommendedPolicyType Standard Get-ConfigAnalyzerPolicyRecommendation -RecommendedPolicyType Strict | M7: — (nur Analyse) | N7: Defender-Portal > Bedrohungsrichtlinien > Konfigurationsanalyse (Configuration analyzer) > Reiter "Standardempfehlungen" / "Strenge Empfehlungen" | O7: Portal öffnen | P7: Learn | Q7: Dritter Tab 'Configuration drift analysis and history' zeigt bis 90 Tage rückwirkend, wer wann was geändert hat - setzt aktiviertes Unified Auditing voraus. Ideal für Übergabe und Folgetermine.
A8: PRE-05 | B8: Preset Security Policies | C8: Policy-Inventar: verwaiste und deaktivierte Policies | E8: offen | F8: Jede Policy hat eine aktive Regel oder ist bewusst stillgelegt und dokumentiert | G8: — | H8: — | I8: — | J8: — | K8: EOP / MDO | L8: Get-SafeLinksPolicy | ForEach-Object { $n=$_.Name; $r=Get-SafeLinksRule | Where-Object { $_.SafeLinksPolicy -eq $n }; [pscustomobject]@{ Policy=$n; Regel=$r.Name; Status=$r.State; Prio=$r.Priority } } | M8: Enable-SafeLinksRule -Identity "<Regelname>" # bzw. Remove-SafeLinksPolicy fuer echte Karteileichen | N8: Defender-Portal > Bedrohungsrichtlinien > Antispam (Spalten Status / Prioritaet / Typ), analog Antiphishing, Antischadsoftware, Sichere Links, Sichere Anlagen | O8: Portal öffnen | P8: Learn | Q8: Zwei Zustaende, die im Portal schwer zu erkennen sind: (1) Eine Policy OHNE zugehoerige Regel ist im Defender-Portal unsichtbar und wirkt auf niemanden - sie entsteht typischerweise, wenn jemand per PowerShell eine Policy angelegt und die Rule vergessen hat. (2) Eine Policy mit DEAKTIVIERTER Regel existiert sichtbar, wirkt aber ebenfalls nicht. Beide sehen im Cmdlet-Output wie normale Policies aus. Das Audit-Skript weist sie im Abschnitt Policy-Inventar (INV-*) aus und bewertet ihre Werte bewusst nicht - eine Policy ohne Wirkung kann keinen Mangel haben. Beim Assessment entscheiden: reaktivieren, loeschen oder als bewusst stillgelegt dokumentieren.
A9: Anti-Spam inbound
A10: ASI-01 | B10: Anti-Spam inbound | C10: Bulk-Schwellwert (BCL) | E10: offen | F10: 6 | G10: 6 statt 7 | H10: 7 | I10: 6 | J10: 5 | K10: EOP | L10: Get-HostedContentFilterPolicy | Format-Table Name,BulkThreshold | M10: Set-HostedContentFilterPolicy -Identity "Default" -BulkThreshold 6 | N10: Defender-Portal > Bedrohungsrichtlinien > Antispam > <Richtlinie> > "Massen-E-Mail-Schwellenwert & Spameigenschaften" > Schieberegler "Massen-E-Mail-Schwellenwert" | O10: Portal öffnen | P10: Learn | Q10: Empfehlung von 2023 deckt sich exakt mit dem MS-Standard-Preset. Schwelle ist 'größer oder gleich': bei 6 wird auch BCL 6 erfasst. 5 (Strict) fängt spürbar mehr legitimes Marketing ab - erst nach Messung.
A11: ASI-02 | B11: Anti-Spam inbound | C11: Aktion bei Spam (SCL 5/6) | E11: offen | F11: MoveToJmf (Junk) | G11: In Junk zustellen ODER User-Quarantäne mit Benachrichtigung | H11: MoveToJmf | I11: MoveToJmf | J11: Quarantine | K11: EOP | L11: Get-HostedContentFilterPolicy | Format-Table Name,SpamAction,SpamQuarantineTag | M11: Set-HostedContentFilterPolicy -Identity "Default" -SpamAction MoveToJmf | N11: Defender-Portal > Bedrohungsrichtlinien > Antispam > <Richtlinie> > "Aktionen" > Nachrichtenaktionen > Zeile "Spam" | O11: Portal öffnen | P11: Learn | Q11: Gültige Werte: AddXHeader, Delete, ModifySubject, MoveToJmf, Quarantine, Redirect. 'Delete' löscht ohne NDR - im Hardening nicht verwenden.
A12: ASI-03 | B12: Anti-Spam inbound | C12: Aktion bei High Confidence Spam (SCL 7/8/9) | E12: offen | F12: Quarantine + DefaultFullAccessWithNotificationPolicy (MS-konform) ODER AdminOnlyAccessPolicy (strengere Variante, bewusste Abweichung) | G12: In Admin-Quarantäne, keine Benachrichtigung | H12: MoveToJmf | I12: Quarantine + DefaultFullAccessWithNotificationPolicy | J12: Quarantine + DefaultFullAccessWithNotificationPolicy | K12: EOP | L12: Get-HostedContentFilterPolicy | Format-Table Name,HighConfidenceSpamAction,HighConfidenceSpamQuarantineTag | M12: Set-HostedContentFilterPolicy -Identity "Default" -HighConfidenceSpamAction Quarantine -HighConfidenceSpamQuarantineTag DefaultFullAccessWithNotificationPolicy | N12: Defender-Portal > Bedrohungsrichtlinien > Antispam > <Richtlinie> > "Aktionen" > Nachrichtenaktionen > Zeile "Spam mit hoher Sicherheit" | O12: Portal öffnen | P12: Learn | Q12: ABWEICHUNG: Ursprungsdokument will Admin-Quarantäne ohne Benachrichtigung. Das ist strenger als MS, erzeugt aber Support-Last (jeder False Positive landet beim Admin). Entscheidung mit dem Kunden treffen und im Feld 'Notizen' dokumentieren.
A13: ASI-04 | B13: Anti-Spam inbound | C13: Aktion bei Phishing | E13: offen | F13: Quarantine + DefaultFullAccessWithNotificationPolicy | G13: In Admin-Quarantäne | H13: MoveToJmf (Default-Policy) / Quarantine (neu erstellte Policies) | I13: Quarantine + DefaultFullAccessWithNotificationPolicy | J13: Quarantine + DefaultFullAccessWithNotificationPolicy | K13: EOP | L13: Get-HostedContentFilterPolicy | Format-Table Name,PhishSpamAction,PhishQuarantineTag | M13: Set-HostedContentFilterPolicy -Identity "Default" -PhishSpamAction Quarantine -PhishQuarantineTag DefaultFullAccessWithNotificationPolicy | N13: Defender-Portal > Bedrohungsrichtlinien > Antispam > <Richtlinie> > "Aktionen" > Nachrichtenaktionen > Zeile "Phishing" | O13: Portal öffnen | P13: Learn | Q13: Achtung: die Default-Policy steht ab Werk auf MoveToJmf - Phishing landet also im Junk-Ordner und ist für den Nutzer erreichbar. Das ist einer der wichtigsten Quick Wins.
A14: ASI-05 | B14: Anti-Spam inbound | C14: Aktion bei High Confidence Phishing | E14: offen | F14: Quarantine + AdminOnlyAccessPolicy | G14: In Admin-Quarantäne | H14: Quarantine + AdminOnlyAccessPolicy | I14: Quarantine + AdminOnlyAccessPolicy | J14: Quarantine + AdminOnlyAccessPolicy | K14: EOP | L14: Get-HostedContentFilterPolicy | Format-Table Name,HighConfidencePhishAction,HighConfidencePhishQuarantineTag | M14: Set-HostedContentFilterPolicy -Identity "Default" -HighConfidencePhishAction Quarantine -HighConfidencePhishQuarantineTag AdminOnlyAccessPolicy | N14: Defender-Portal > Bedrohungsrichtlinien > Antispam > <Richtlinie> > "Aktionen" > Nachrichtenaktionen > Zeile "Phishing mit hoher Sicherheit" | O14: Portal öffnen | P14: Learn | Q14: HighConfidencePhishAction kennt nur Quarantine und Redirect - MoveToJmf ist nicht möglich. Empfehlung von 2023 ist hier identisch mit dem MS-Default.
A15: ASI-06 | B15: Anti-Spam inbound | C15: Aktion bei Bulk (BCL-Schwelle erreicht) | E15: offen | F15: MoveToJmf | G15: eigene Action für 'BCL met or exceeded' festlegen | H15: MoveToJmf | I15: MoveToJmf | J15: Quarantine + DefaultFullAccessWithNotificationPolicy | K15: EOP | L15: Get-HostedContentFilterPolicy | Format-Table Name,BulkSpamAction,BulkQuarantineTag,MarkAsSpamBulkMail | M15: Set-HostedContentFilterPolicy -Identity "Default" -BulkSpamAction MoveToJmf | N15: Defender-Portal > Bedrohungsrichtlinien > Antispam > <Richtlinie> > "Aktionen" > Nachrichtenaktionen > Zeile "Massenkonforme Ebene (BCL) erreicht oder ueberschritten" | O15: Portal öffnen | P15: Learn | Q15: BulkSpamAction ist der einzige Aktions-Parameter mit dem Wert 'NoAction'. MarkAsSpamBulkMail muss auf 'On' bleiben, sonst wirkt die BCL-Schwelle faktisch nicht.
A16: ASI-07 | B16: Anti-Spam inbound | C16: Spam Safety Tips (farbige Inline-Warnung) | E16: offen | F16: $true | G16: ein | H16: $true | I16: $true | J16: $true | K16: EOP | L16: Get-HostedContentFilterPolicy | Format-Table Name,InlineSafetyTipsEnabled | M16: Set-HostedContentFilterPolicy -Identity "Default" -InlineSafetyTipsEnabled $true | N16: Defender-Portal > Bedrohungsrichtlinien > Antispam > <Richtlinie> > "Aktionen" > Abschnitt "Sicherheitstipps" > Haken "Sicherheitstipps aktivieren" | O16: Portal öffnen | P16: Learn | Q16: Nicht abschalten. Kostet nichts, ist in allen Presets aktiv.
A17: ASI-08 | B17: Anti-Spam inbound | C17: ZAP für Spam und Phishing | E17: offen | F17: SpamZapEnabled $true, PhishZapEnabled $true | G17: ein | H17: beide $true | I17: beide $true | J17: beide $true | K17: EOP | L17: Get-HostedContentFilterPolicy | Format-Table Name,SpamZapEnabled,PhishZapEnabled | M17: Set-HostedContentFilterPolicy -Identity "Default" -SpamZapEnabled $true -PhishZapEnabled $true | N17: Defender-Portal > Bedrohungsrichtlinien > Antispam > <Richtlinie> > "Aktionen" > "Automatische Bereinigung (ZAP) aktivieren" mit den zwei Unterhaken fuer Phishing und Spam | O17: Portal öffnen | P17: Learn | Q17: ÄNDERUNG seit 2023: der Sammelparameter 'ZapEnabled' existiert in Set-HostedContentFilterPolicy NICHT mehr. Er wurde in SpamZapEnabled und PhishZapEnabled aufgeteilt. Malware-ZAP sitzt in der Anti-Malware-Policy (AMW-02).
A18: ASI-09 | B18: Anti-Spam inbound | C18: Quarantäne-Aufbewahrung | E18: offen | F18: 30 Tage | G18: — | H18: 15 | I18: 30 | J18: 30 | K18: EOP | L18: Get-HostedContentFilterPolicy | Format-Table Name,QuarantineRetentionPeriod | M18: Set-HostedContentFilterPolicy -Identity "Default" -QuarantineRetentionPeriod 30 | N18: Defender-Portal > Bedrohungsrichtlinien > Antispam > <Richtlinie> > "Aktionen" > Feld "Spamnachrichten so viele Tage lang in Quarantaene aufbewahren" (1-30, Default 15) | O18: Portal öffnen | P18: Learn | Q18: Maximum ist 30 Tage, mehr geht nicht. Der Wert wirkt auch auf Nachrichten, die durch die Anti-Phishing-Policy quarantäniert wurden. Anti-Malware und Safe Attachments sind fix auf 30 Tage und nicht konfigurierbar.
A19: ASI-10 | B19: Anti-Spam inbound | C19: Allowed senders / allowed sender domains leer bzw. begründet | E19: offen | F19: Leer. Ausnahmen ausschließlich über die Tenant Allow/Block List (TABL-01). | G19: Whitelisting sender/domain based möglich | H19: leer | I19: leer | J19: leer | K19: EOP | L19: Get-HostedContentFilterPolicy | Format-List Name,AllowedSenders,AllowedSenderDomains,BlockedSenders,BlockedSenderDomains | M19: Set-HostedContentFilterPolicy -Identity "Default" -AllowedSenderDomains @{} | N19: Defender-Portal > Bedrohungsrichtlinien > Antispam > <Richtlinie> > "Zulassen- und Sperrliste" > "Absender verwalten" / "Domaenen zulassen" (im Portal max. 30 Eintraege) | O19: Portal öffnen | P19: Learn | Q19: KRITISCH: AllowedSenderDomains setzt SCL -1 und überspringt die komplette Spam- und Phishing-Filterung. Eine gespoofte Absenderdomain aus dieser Liste geht ungefiltert in den Posteingang. MS wörtlich: 'Think very carefully before you add domains here.'
A20: ASI-11 | B20: Anti-Spam inbound | C20: Sprach- und Länderfilter | E20: offen | F20: Aus, sofern kein konkreter Anlass. Bei Einsatz: Trefferliste vorher per Threat Explorer messen. | G20: Blacklisting country based / language based verfügbar | H20: aus | I20: aus | J20: aus | K20: EOP | L20: Get-HostedContentFilterPolicy | Format-List Name,EnableLanguageBlockList,LanguageBlockList,EnableRegionBlockList,RegionBlockList | M20: Set-HostedContentFilterPolicy -Identity "Default" -EnableRegionBlockList $false -EnableLanguageBlockList $false | N20: Defender-Portal > Bedrohungsrichtlinien > Antispam > <Richtlinie> > "Massen-E-Mail-Schwellenwert & Spameigenschaften" > Spameigenschaften > "Enthaelt bestimmte Sprachen" / "Aus diesen Laendern" (gehoert NICHT zum ASF) | O20: Portal öffnen | P20: Learn | Q20: Microsoft gibt hierzu ausdrücklich KEINE Empfehlung ab ('We have no specific recommendation for this setting') - warnt aber auch nicht davor. Kein Preset aktiviert es. Sprache wird aus dem Nachrichteninhalt geraten, Land aus der Quell-IP - beides umgehbar.
A21: ASI-12 | B21: Anti-Spam inbound | C21: Intra-Organizational Filtering (interne Nachrichten) | E21: offen | F21: Default (= High Confidence Phishing) | G21: — | H21: Default | I21: Default | J21: Default | K21: EOP | L21: Get-HostedContentFilterPolicy | Format-Table Name,IntraOrgFilterState | M21: Set-HostedContentFilterPolicy -Identity "Default" -IntraOrgFilterState Default | N21: Defender-Portal > Bedrohungsrichtlinien > Antispam > <Richtlinie> > "Aktionen" > "Organisationsinterne Nachrichten, fuer die Massnahmen ergriffen werden sollen" | O21: Portal öffnen | P21: Learn | Q21: Neu gegenüber dem Ursprungsdokument. Werte: Default, HighConfidencePhish, Phish, HighConfidenceSpam, Spam, Disabled. Relevant bei kompromittierten internen Konten - erst nach Test verschärfen, sonst Fehlalarme auf internen Serienmails.
A22: Advanced Spam Filter (ASF)
A23: ASF-01 | B23: Advanced Spam Filter (ASF) | C23: ASF-Features zur Score-Erhöhung (Image links, Numeric IP, URL redirect, .biz/.info) | E23: offen | F23: Off (alle vier) | G23: Auswahlliste vorhanden - im Dokument gelistet, ohne Aktivierungsempfehlung | H23: Off | I23: Off (nicht Teil des Presets) | J23: Off (nicht Teil des Presets) | K23: EOP | L23: Get-HostedContentFilterPolicy | Format-List Name,IncreaseScoreWithImageLinks,IncreaseScoreWithNumericIps,IncreaseScoreWithRedirectToOtherPort,IncreaseScoreWithBizOrInfoUrls | M23: Set-HostedContentFilterPolicy -Identity "Default" -IncreaseScoreWithImageLinks Off -IncreaseScoreWithNumericIps Off -IncreaseScoreWithRedirectToOtherPort Off -IncreaseScoreWithBizOrInfoUrls Off | N23: Defender-Portal > Bedrohungsrichtlinien > Antispam > <Richtlinie> > "Massen-E-Mail-Schwellenwert & Spameigenschaften" > Spameigenschaften > Gruppe "Erhoehen der Spambewertung" | O23: Portal öffnen | P23: Learn | Q23: Werte je Parameter: Off | On | Test. MS wörtlich: 'Enabling one or more of the ASF settings is an aggressive approach to spam filtering.' Und entscheidend: durch ASF gefilterte Nachrichten können NICHT als False Positive an Microsoft gemeldet werden - kein Feedback-Loop.
A24: ASF-02 | B24: Advanced Spam Filter (ASF) | C24: ASF-Features 'Mark as Spam' (Empty messages, HTML-Tags, Web bugs, Sensitive words u.a.) | E24: offen | F24: Off (alle acht) | G24: Auswahlliste vorhanden - im Dokument gelistet | H24: Off | I24: Off | J24: Off | K24: EOP | L24: Get-HostedContentFilterPolicy | Format-List Name,MarkAsSpamEmptyMessages,MarkAsSpamEmbedTagsInHtml,MarkAsSpamJavaScriptInHtml,MarkAsSpamFormTagsInHtml,MarkAsSpamFramesInHtml,MarkAsSpamWebBugsInHtml,MarkAsSpamObjectTagsInHtml,MarkAsSpamSensitiveWordList | M24: Set-HostedContentFilterPolicy -Identity "Default" -MarkAsSpamEmptyMessages Off -MarkAsSpamEmbedTagsInHtml Off -MarkAsSpamJavaScriptInHtml Off -MarkAsSpamFormTagsInHtml Off -MarkAsSpamFramesInHtml Off -MarkAsSpamWebBugsInHtml Off -MarkAsSpamObjectTagsInHtml Off -MarkAsSpamSensitiveWordList Off | N24: Defender-Portal > Bedrohungsrichtlinien > Antispam > <Richtlinie> > "Massen-E-Mail-Schwellenwert & Spameigenschaften" > Spameigenschaften > Gruppe "Als Spam markieren" | O24: Portal öffnen | P24: Learn | Q24: Diese Treffer setzen SCL 9 (High Confidence Spam). Newsletter mit Tracking-Pixel oder eingebettetem Formular sind damit sofort HC-Spam. Wer ASF aktiviert, kann für die betroffenen Empfänger die Standard/Strict-Presets nicht mehr nutzen.
A25: ASF-03 | B25: Advanced Spam Filter (ASF) | C25: SPF Hard Fail als Spam-Kriterium | E25: offen | F25: Off — die Frage im Ursprungsdokument ist mit NEIN beantwortet | G25: Frage im Dokument offen gelassen: 'Das Spam-Feature ist also nicht mehr benötigt?' | H25: Off | I25: Off | J25: Off | K25: EOP | L25: Get-HostedContentFilterPolicy | Format-Table Name,MarkAsSpamSpfRecordHardFail | M25: Set-HostedContentFilterPolicy -Identity "Default" -MarkAsSpamSpfRecordHardFail Off | N25: Defender-Portal > Bedrohungsrichtlinien > Antispam > <Richtlinie> > "Massen-E-Mail-Schwellenwert & Spameigenschaften" > Spameigenschaften > "SPF-Eintrag: Hard Fail" | O25: Portal öffnen | P25: Learn | Q25: Microsoft beantwortet die Frage in der Anti-Spoofing-FAQ wörtlich: 'No. This ASF setting is no longer required. (...) you will probably get more false positives.' Die Vermutung im Ursprungsdokument war also richtig - jetzt belegt.
A26: ASF-04 | B26: Advanced Spam Filter (ASF) | C26: Sender-ID Hard Fail und NDR-Backscatter | E26: offen | F26: Off (beide) | G26: 'Sender ID filtering hard fail' und 'Backscatter' in der Feature-Liste genannt | H26: Off | I26: Off | J26: Off | K26: EOP | L26: Get-HostedContentFilterPolicy | Format-Table Name,MarkAsSpamFromAddressAuthFail,MarkAsSpamNdrBackscatter | M26: Set-HostedContentFilterPolicy -Identity "Default" -MarkAsSpamFromAddressAuthFail Off -MarkAsSpamNdrBackscatter Off | N26: Defender-Portal > Bedrohungsrichtlinien > Antispam > <Richtlinie> > "Massen-E-Mail-Schwellenwert & Spameigenschaften" > Spameigenschaften > "Absender-ID-Filterung: Hard Fail" und "Backscatter" | O26: Portal öffnen | P26: Learn | Q26: NAMENSKORREKTUR: Der Parameter heißt MarkAsSpamFromAddressAuthFail, NICHT MarkAsSpamSenderIdHardFail (den gibt es nicht). Sender ID ist ein abgelöstes Verfahren. Backscatter wird von der regulären Filterung mit abgedeckt.
A27: ASF-05 | B27: Advanced Spam Filter (ASF) | C27: ASF Test-Modus | E27: offen | F27: None | G27: — | H27: None | I27: None | J27: None | K27: EOP | L27: Get-HostedContentFilterPolicy | Format-Table Name,TestModeAction,TestModeBccToRecipients | M27: Set-HostedContentFilterPolicy -Identity "Default" -TestModeAction None | N27: Defender-Portal > Bedrohungsrichtlinien > Antispam > <Richtlinie> > "Massen-E-Mail-Schwellenwert & Spameigenschaften" > Spameigenschaften > "Testmodus" (gilt global fuer alle auf Test gesetzten ASF-Optionen) | O27: Portal öffnen | P27: Learn | Q27: Falls ASF doch einmal erprobt werden soll: erst alle gewünschten Settings auf 'Test' und TestModeAction auf AddXHeader, dann Trefferquote im Message Trace messen. TestModeAction gilt global für alle Test-Settings, nicht je Setting.
A28: Connection Filter
A29: CF-01 | B29: Connection Filter | C29: IP Allow List | E29: offen | F29: Leer. Falls unvermeidbar: einzelne /32, dokumentiert, mit Ablaufdatum im Betriebshandbuch. | G29: wo benötigt, aber Vorsicht | H29: leer | I29: nicht Teil des Presets | J29: nicht Teil des Presets | K29: EOP | L29: Get-HostedConnectionFilterPolicy -Identity Default | Format-List IPAllowList,IPBlockList,EnableSafeList | M29: Set-HostedConnectionFilterPolicy -Identity Default -IPAllowList @{} | N29: Defender-Portal > Bedrohungsrichtlinien > Antispam > in der Liste die Zeile "Verbindungsfilterrichtlinie (Standard)" ANKLICKEN > Flyout > "Verbindungsfilterrichtlinie bearbeiten" > "Nachrichten aus den folgenden IP-Adressen immer zulassen" | O29: Portal öffnen | P29: Learn | Q29: Die Vorsicht im Ursprungsdokument ist berechtigt: IPAllowList setzt SCL -1 und überspringt Spam-, Phishing-, Bulk- und Spoof-Prüfung. Malware und High Confidence Phishing werden weiterhin geprüft. MS listet die IP Allow List als ZWEITSCHLECHTESTE aller Allow-Methoden.
A30: CF-02 | B30: Connection Filter | C30: IP Block List | E30: offen | F30: Nur bei konkretem Anlass; IPv4-Blocks gehören hierher (nicht in die TABL). | G30: Blacklisting IP-address based | H30: leer | I30: — | J30: — | K30: EOP | L30: Get-HostedConnectionFilterPolicy -Identity Default | Format-List IPBlockList | M30: Set-HostedConnectionFilterPolicy -Identity Default -IPBlockList @{Add="203.0.113.10"} | N30: Defender-Portal > Bedrohungsrichtlinien > Antispam > Zeile "Verbindungsfilterrichtlinie (Standard)" > "Verbindungsfilterrichtlinie bearbeiten" > "Nachrichten aus den folgenden IP-Adressen immer blockieren" | O30: Portal öffnen | P30: Learn | Q30: Max. 1.273 Einträge, CIDR nur /24 bis /32, kein IPv6. Für IPv6 die TABL nutzen. Blockierte Nachrichten sind NICHT im Message Trace sichtbar - klassische Troubleshooting-Falle.
A31: CF-03 | B31: Connection Filter | C31: Safe List (EnableSafeList) | E31: offen | F31: $false | G31: — | H31: $false | I31: — | J31: — | K31: EOP | L31: Get-HostedConnectionFilterPolicy -Identity Default | Format-Table EnableSafeList | M31: Set-HostedConnectionFilterPolicy -Identity Default -EnableSafeList $false | N31: Defender-Portal > Bedrohungsrichtlinien > Antispam > Zeile "Verbindungsfilterrichtlinie (Standard)" > "Verbindungsfilterrichtlinie bearbeiten" > Haken "Sichere Liste aktivieren" | O31: Portal öffnen | P31: Learn | Q31: Doku-Widerspruch: der Konfigurationsartikel beschreibt es als reguläres Feature, die Cmdlet-Referenz kennzeichnet den Parameter als 'reserved for internal Microsoft use'. Faktisch ein pauschaler Filter-Skip für eine Serverliste, die der Kunde nicht einsehen kann. Ausgeschaltet lassen.
A32: Anti-Spam outbound
A33: ASO-01 | B33: Anti-Spam outbound | C33: Eigene Outbound-Policy vs. Default-Policy | E33: offen | F33: Grenzwerte und Aktion in der DEFAULT-Policy setzen; eigene Policies nur für begründete Ausnahmen (z.B. Versand-Postfach). | G33: eigene erstellen | H33: Default-Policy hat feste Priorität 'Lowest' und keine Rule | I33: — | J33: — | K33: EOP | L33: Get-HostedOutboundSpamFilterPolicy | Format-List Name,RecipientLimitExternalPerHour,RecipientLimitInternalPerHour,RecipientLimitPerDay,ActionWhenThresholdReached,AutoForwardingMode,BccSuspiciousOutboundMail,NotifyOutboundSpam | M33: Set-HostedOutboundSpamFilterPolicy -Identity "Default" -RecipientLimitExternalPerHour 500 | N33: Defender-Portal > Bedrohungsrichtlinien > Antispam > Liste auf "Ausgehende Antispamrichtlinie (Standard)" und eigene Richtlinien pruefen; neu ueber "+ Richtlinie erstellen > Ausgehend" | O33: Portal öffnen | P33: Learn | Q33: ABWEICHUNG zur Empfehlung von 2023: BccSuspiciousOutboundMail wirkt NUR in der Default-Policy, nicht in Custom-Policies. Wer alles in eine eigene Policy legt, verliert diese Funktion.
A34: ASO-02 | B34: Anti-Spam outbound | C34: Empfänger-Limits (extern/intern/Tag) | E34: offen | F34: Extern 500/h, intern 1000/h, 1000/Tag (= MS Standard). 200/Tag nur, wenn im Tenant nachweislich kein legitimer Serienversand existiert. | G34: max. 200 pro Tag | H34: 0 / 0 / 0 (= Service-Defaults) | I34: 500 / 1000 / 1000 | J34: 400 / 800 / 800 | K34: EOP | L34: Get-HostedOutboundSpamFilterPolicy | Format-Table Name,RecipientLimitExternalPerHour,RecipientLimitInternalPerHour,RecipientLimitPerDay | M34: Set-HostedOutboundSpamFilterPolicy -Identity "Default" -RecipientLimitExternalPerHour 500 -RecipientLimitInternalPerHour 1000 -RecipientLimitPerDay 1000 | N34: Defender-Portal > Bedrohungsrichtlinien > Antispam > <ausgehende Richtlinie> > "Schutzeinstellungen" > Nachrichtengrenzwerte (extern / intern / taeglich) | O34: Portal öffnen | P34: Learn | Q34: ABWEICHUNG: 200/Tag ist deutlich strenger als MS Strict (800). Für Vertrieb, Personalabteilung oder Rechnungsversand ist das zu eng und erzeugt gesperrte Nutzer. Empfehlung: mit MS-Standard starten, tatsächliche Spitzen im Report messen, dann bewusst absenken. Wertebereich 0-10000, 0 = Service-Default.
A35: ASO-03 | B35: Anti-Spam outbound | C35: Aktion bei Erreichen der Limits | E35: offen | F35: BlockUser (= MS Standard/Strict) + Alert Policy 'User restricted from sending email' mit gepflegten Empfängern | G35: Send Admin-Alert | H35: BlockUserForToday | I35: BlockUser | J35: BlockUser | K35: EOP | L35: Get-HostedOutboundSpamFilterPolicy | Format-Table Name,ActionWhenThresholdReached | M35: Set-HostedOutboundSpamFilterPolicy -Identity "Default" -ActionWhenThresholdReached BlockUser | N35: Defender-Portal > Bedrohungsrichtlinien > Antispam > <ausgehende Richtlinie> > "Schutzeinstellungen" > "Einschraenkung fuer Benutzer, die das Nachrichtenlimit erreichen" | O35: Portal öffnen | P35: Learn | Q35: Gültige Werte NUR: Alert, BlockUser, BlockUserForToday. 'BlockUserForever' oder 'AlertOnly' existieren nicht. BlockUser sperrt bis zur manuellen Admin-Freigabe unter security.microsoft.com/restrictedusers - das ist der Punkt, an dem ein kompromittiertes Konto gestoppt wird.
A36: ASO-04 | B36: Anti-Spam outbound | C36: Automatische externe Weiterleitungen | E36: offen | F36: Automatic (= systemgesteuert = aus) | G36: — (im Ursprungsdokument nicht enthalten) | H36: Automatic | I36: Automatic | J36: Automatic | K36: EOP | L36: Get-HostedOutboundSpamFilterPolicy | Format-Table Name,AutoForwardingMode | M36: Set-HostedOutboundSpamFilterPolicy -Identity "Default" -AutoForwardingMode Automatic | N36: Defender-Portal > Bedrohungsrichtlinien > Antispam > <ausgehende Richtlinie> > "Schutzeinstellungen" > Weiterleitungsregeln > "Automatische Weiterleitungsregeln" | O36: Portal öffnen | P36: Learn | Q36: WICHTIGE LÜCKE im Ursprungsdokument. 'Automatic - System-controlled' ist laut MS gleichbedeutend mit 'Off'. Automatische externe Weiterleitung ist der Standard-Exfiltrationsweg nach einer Kontokompromittierung. Betrifft Posteingangsregeln UND Mailbox-Forwarding. Ausnahmen nur über eine eng gescopte Custom-Policy mit 'On'.
A37: ASO-05 | B37: Anti-Spam outbound | C37: Benachrichtigung/BCC bei verdächtigem Ausgangsverkehr | E37: offen | F37: Bewusste Entscheidung: MS-Preset-konform ($false, Alert Policy nutzen) ODER Secure-Score-konform ($true). | G37: Send Admin-Alert | H37: $false | I37: $false | J37: $false | K37: EOP | L37: Get-HostedOutboundSpamFilterPolicy | Format-List Name,BccSuspiciousOutboundMail,BccSuspiciousOutboundAdditionalRecipients,NotifyOutboundSpam,NotifyOutboundSpamRecipients | M37: Set-HostedOutboundSpamFilterPolicy -Identity "Default" -NotifyOutboundSpam $false | N37: Defender-Portal > Bedrohungsrichtlinien > Antispam > "Ausgehende Antispamrichtlinie (Standard)" > "Schutzeinstellungen" > Benachrichtigungen (BCC-Kopie); gesperrte Absender unter Defender-Portal > Ueberpruefen > Eingeschraenkte Benutzer | O37: Portal öffnen | P37: Learn | Q37: ZIELKONFLIKT, den Microsoft selbst dokumentiert: NotifyOutboundSpam ist 'in the process of being deprecated', die Secure-Score-Empfehlung 'Ensure Exchange Online Spam Policies are set to notify administrators' verlangt es trotzdem. Wer den Presets folgt, verliert Secure-Score-Punkte. Entscheidung dokumentieren.
A38: ASO-06 | B38: Anti-Spam outbound | C38: Tenant External Recipient Rate Limit (TERRL) bekannt und eingeplant | E38: offen | F38: Kunde kennt das Limit; Massenversand läuft nicht über EXO | G38: — (2023 noch nicht existent) | H38: skaliert mit der Lizenzanzahl; Trial-Tenants 5.000 externe Empfänger/Tag | I38: — | J38: — | K38: EOP | L38: # kein Cmdlet - Symptom ist der NDR: # 550 5.7.233 ... tenant external recipient rate limit | M38: — (nicht konfigurierbar) | N38: Nicht konfigurierbar (mandantenweites Limit). Auswertung: Exchange Admin Center > Berichte > Nachrichtenfluss > "Tenant Outbound External Recipients" | O38: Portal öffnen | P38: Learn | Q38: Neu seit 2025. Harte Service-Limits daneben: 10.000 Empfänger/Tag pro Postfach, 30 Nachrichten/Minute, 500 Empfänger je Nachricht. Verteilergruppen zählen mit jedem einzelnen Mitglied. Newsletter gehören auf einen dedizierten Versanddienst, nicht in EXO.
A39: Anti-Phishing / Spoof
A40: APH-01 | B40: Anti-Phishing / Spoof | C40: Spoof Intelligence aktiv | E40: offen | F40: $true | G40: ein | H40: $true | I40: $true | J40: $true | K40: EOP | L40: Get-AntiPhishPolicy | Format-Table Name,Enabled,EnableSpoofIntelligence | M40: Set-AntiPhishPolicy -Identity "Office365 AntiPhish Default" -EnableSpoofIntelligence $true | N40: Defender-Portal > Bedrohungsrichtlinien > Antiphishing > <Richtlinie> > "Phishingschwellenwert & Schutz" > Abschnitt "Spoofing" > "Spoofintelligenz aktivieren" | O40: Portal öffnen | P40: Learn | Q40: WICHTIGE ÄNDERUNG: EnableSpoofIntelligence $false schaltet nur den IMPLIZITEN Spoof-Schutz (Composite Authentication) ab. Die EXPLIZITE DMARC-Durchsetzung über HonorDmarcPolicy bleibt davon unberührt. Ältere Guides, die das gleichsetzen, sind überholt.
...

Sheet Auswertung
B2: Auswertung
B3: Die Werte aktualisieren sich automatisch aus dem Blatt „Checkliste“.
B5: Gesamtübersicht
B6: Bewertung | C6: Anzahl | D6: Anteil
B7: offen | C7: =COUNTIFS(Checkliste!$A$3:$A$148,"<>",Checkliste!$E$3:$E$148,B7) -> 120 | D7: =IFERROR(C7/$C$13,0) -> 1
B8: OK | C8: =COUNTIFS(Checkliste!$A$3:$A$148,"<>",Checkliste!$E$3:$E$148,B8) -> 0 | D8: =IFERROR(C8/$C$13,0) -> 0
B9: Verbesserung empfohlen | C9: =COUNTIFS(Checkliste!$A$3:$A$148,"<>",Checkliste!$E$3:$E$148,B9) -> 0 | D9: =IFERROR(C9/$C$13,0) -> 0
B10: Kritisch | C10: =COUNTIFS(Checkliste!$A$3:$A$148,"<>",Checkliste!$E$3:$E$148,B10) -> 0 | D10: =IFERROR(C10/$C$13,0) -> 0
B11: n.a. (nicht lizenziert) | C11: =COUNTIFS(Checkliste!$A$3:$A$148,"<>",Checkliste!$E$3:$E$148,B11) -> 0 | D11: =IFERROR(C11/$C$13,0) -> 0
B12: bewusst abgewichen | C12: =COUNTIFS(Checkliste!$A$3:$A$148,"<>",Checkliste!$E$3:$E$148,B12) -> 0 | D12: =IFERROR(C12/$C$13,0) -> 0
B13: Prüfpunkte gesamt | C13: =COUNTA(Checkliste!$A$3:$A$148)-COUNTBLANK(Checkliste!$E$3:$E$148) -> 120
B15: Nach Kategorie
B16: Kategorie | C16: Prüfpunkte | D16: OK | E16: Verbesserung | F16: Kritisch | G16: bewusst abgew. | H16: n.a. | I16: offen
B17: Preset Security Policies | C17: =COUNTIFS(Checkliste!$B$3:$B$148,$B17,Checkliste!$A$3:$A$148,"<>") -> 5 | D17: =COUNTIFS(Checkliste!$B$3:$B$148,$B17,Checkliste!$E$3:$E$148,"OK") -> 0 | E17: =COUNTIFS(Checkliste!$B$3:$B$148,$B17,Checkliste!$E$3:$E$148,"Verbesserung empfohlen") -> 0 | F17: =COUNTIFS(Checkliste!$B$3:$B$148,$B17,Checkliste!$E$3:$E$148,"Kritisch") -> 0 | G17: =COUNTIFS(Checkliste!$B$3:$B$148,$B17,Checkliste!$E$3:$E$148,"bewusst abgewichen") -> 0 | H17: =COUNTIFS(Checkliste!$B$3:$B$148,$B17,Checkliste!$E$3:$E$148,"n.a. (nicht lizenziert)") -> 0 | I17: =COUNTIFS(Checkliste!$B$3:$B$148,$B17,Checkliste!$E$3:$E$148,"offen") -> 5
B18: Anti-Spam inbound | C18: =COUNTIFS(Checkliste!$B$3:$B$148,$B18,Checkliste!$A$3:$A$148,"<>") -> 12 | D18: =COUNTIFS(Checkliste!$B$3:$B$148,$B18,Checkliste!$E$3:$E$148,"OK") -> 0 | E18: =COUNTIFS(Checkliste!$B$3:$B$148,$B18,Checkliste!$E$3:$E$148,"Verbesserung empfohlen") -> 0 | F18: =COUNTIFS(Checkliste!$B$3:$B$148,$B18,Checkliste!$E$3:$E$148,"Kritisch") -> 0 | G18: =COUNTIFS(Checkliste!$B$3:$B$148,$B18,Checkliste!$E$3:$E$148,"bewusst abgewichen") -> 0 | H18: =COUNTIFS(Checkliste!$B$3:$B$148,$B18,Checkliste!$E$3:$E$148,"n.a. (nicht lizenziert)") -> 0 | I18: =COUNTIFS(Checkliste!$B$3:$B$148,$B18,Checkliste!$E$3:$E$148,"offen") -> 12
B19: Advanced Spam Filter (ASF) | C19: =COUNTIFS(Checkliste!$B$3:$B$148,$B19,Checkliste!$A$3:$A$148,"<>") -> 5 | D19: =COUNTIFS(Checkliste!$B$3:$B$148,$B19,Checkliste!$E$3:$E$148,"OK") -> 0 | E19: =COUNTIFS(Checkliste!$B$3:$B$148,$B19,Checkliste!$E$3:$E$148,"Verbesserung empfohlen") -> 0 | F19: =COUNTIFS(Checkliste!$B$3:$B$148,$B19,Checkliste!$E$3:$E$148,"Kritisch") -> 0 | G19: =COUNTIFS(Checkliste!$B$3:$B$148,$B19,Checkliste!$E$3:$E$148,"bewusst abgewichen") -> 0 | H19: =COUNTIFS(Checkliste!$B$3:$B$148,$B19,Checkliste!$E$3:$E$148,"n.a. (nicht lizenziert)") -> 0 | I19: =COUNTIFS(Checkliste!$B$3:$B$148,$B19,Checkliste!$E$3:$E$148,"offen") -> 5
B20: Connection Filter | C20: =COUNTIFS(Checkliste!$B$3:$B$148,$B20,Checkliste!$A$3:$A$148,"<>") -> 3 | D20: =COUNTIFS(Checkliste!$B$3:$B$148,$B20,Checkliste!$E$3:$E$148,"OK") -> 0 | E20: =COUNTIFS(Checkliste!$B$3:$B$148,$B20,Checkliste!$E$3:$E$148,"Verbesserung empfohlen") -> 0 | F20: =COUNTIFS(Checkliste!$B$3:$B$148,$B20,Checkliste!$E$3:$E$148,"Kritisch") -> 0 | G20: =COUNTIFS(Checkliste!$B$3:$B$148,$B20,Checkliste!$E$3:$E$148,"bewusst abgewichen") -> 0 | H20: =COUNTIFS(Checkliste!$B$3:$B$148,$B20,Checkliste!$E$3:$E$148,"n.a. (nicht lizenziert)") -> 0 | I20: =COUNTIFS(Checkliste!$B$3:$B$148,$B20,Checkliste!$E$3:$E$148,"offen") -> 3
B21: Anti-Spam outbound | C21: =COUNTIFS(Checkliste!$B$3:$B$148,$B21,Checkliste!$A$3:$A$148,"<>") -> 8 | D21: =COUNTIFS(Checkliste!$B$3:$B$148,$B21,Checkliste!$E$3:$E$148,"OK") -> 0 | E21: =COUNTIFS(Checkliste!$B$3:$B$148,$B21,Checkliste!$E$3:$E$148,"Verbesserung empfohlen") -> 0 | F21: =COUNTIFS(Checkliste!$B$3:$B$148,$B21,Checkliste!$E$3:$E$148,"Kritisch") -> 0 | G21: =COUNTIFS(Checkliste!$B$3:$B$148,$B21,Checkliste!$E$3:$E$148,"bewusst abgewichen") -> 0 | H21: =COUNTIFS(Checkliste!$B$3:$B$148,$B21,Checkliste!$E$3:$E$148,"n.a. (nicht lizenziert)") -> 0 | I21: =COUNTIFS(Checkliste!$B$3:$B$148,$B21,Checkliste!$E$3:$E$148,"offen") -> 8
B22: Anti-Phishing / Spoof | C22: =COUNTIFS(Checkliste!$B$3:$B$148,$B22,Checkliste!$A$3:$A$148,"<>") -> 8 | D22: =COUNTIFS(Checkliste!$B$3:$B$148,$B22,Checkliste!$E$3:$E$148,"OK") -> 0 | E22: =COUNTIFS(Checkliste!$B$3:$B$148,$B22,Checkliste!$E$3:$E$148,"Verbesserung empfohlen") -> 0 | F22: =COUNTIFS(Checkliste!$B$3:$B$148,$B22,Checkliste!$E$3:$E$148,"Kritisch") -> 0 | G22: =COUNTIFS(Checkliste!$B$3:$B$148,$B22,Checkliste!$E$3:$E$148,"bewusst abgewichen") -> 0 | H22: =COUNTIFS(Checkliste!$B$3:$B$148,$B22,Checkliste!$E$3:$E$148,"n.a. (nicht lizenziert)") -> 0 | I22: =COUNTIFS(Checkliste!$B$3:$B$148,$B22,Checkliste!$E$3:$E$148,"offen") -> 8
B23: Impersonation (MDO) | C23: =COUNTIFS(Checkliste!$B$3:$B$148,$B23,Checkliste!$A$3:$A$148,"<>") -> 8 | D23: =COUNTIFS(Checkliste!$B$3:$B$148,$B23,Checkliste!$E$3:$E$148,"OK") -> 0 | E23: =COUNTIFS(Checkliste!$B$3:$B$148,$B23,Checkliste!$E$3:$E$148,"Verbesserung empfohlen") -> 0 | F23: =COUNTIFS(Checkliste!$B$3:$B$148,$B23,Checkliste!$E$3:$E$148,"Kritisch") -> 0 | G23: =COUNTIFS(Checkliste!$B$3:$B$148,$B23,Checkliste!$E$3:$E$148,"bewusst abgewichen") -> 0 | H23: =COUNTIFS(Checkliste!$B$3:$B$148,$B23,Checkliste!$E$3:$E$148,"n.a. (nicht lizenziert)") -> 0 | I23: =COUNTIFS(Checkliste!$B$3:$B$148,$B23,Checkliste!$E$3:$E$148,"offen") -> 8
B24: Tenant Allow/Block List | C24: =COUNTIFS(Checkliste!$B$3:$B$148,$B24,Checkliste!$A$3:$A$148,"<>") -> 6 | D24: =COUNTIFS(Checkliste!$B$3:$B$148,$B24,Checkliste!$E$3:$E$148,"OK") -> 0 | E24: =COUNTIFS(Checkliste!$B$3:$B$148,$B24,Checkliste!$E$3:$E$148,"Verbesserung empfohlen") -> 0 | F24: =COUNTIFS(Checkliste!$B$3:$B$148,$B24,Checkliste!$E$3:$E$148,"Kritisch") -> 0 | G24: =COUNTIFS(Checkliste!$B$3:$B$148,$B24,Checkliste!$E$3:$E$148,"bewusst abgewichen") -> 0 | H24: =COUNTIFS(Checkliste!$B$3:$B$148,$B24,Checkliste!$E$3:$E$148,"n.a. (nicht lizenziert)") -> 0 | I24: =COUNTIFS(Checkliste!$B$3:$B$148,$B24,Checkliste!$E$3:$E$148,"offen") -> 6
B25: Anti-Malware | C25: =COUNTIFS(Checkliste!$B$3:$B$148,$B25,Checkliste!$A$3:$A$148,"<>") -> 5 | D25: =COUNTIFS(Checkliste!$B$3:$B$148,$B25,Checkliste!$E$3:$E$148,"OK") -> 0 | E25: =COUNTIFS(Checkliste!$B$3:$B$148,$B25,Checkliste!$E$3:$E$148,"Verbesserung empfohlen") -> 0 | F25: =COUNTIFS(Checkliste!$B$3:$B$148,$B25,Checkliste!$E$3:$E$148,"Kritisch") -> 0 | G25: =COUNTIFS(Checkliste!$B$3:$B$148,$B25,Checkliste!$E$3:$E$148,"bewusst abgewichen") -> 0 | H25: =COUNTIFS(Checkliste!$B$3:$B$148,$B25,Checkliste!$E$3:$E$148,"n.a. (nicht lizenziert)") -> 0 | I25: =COUNTIFS(Checkliste!$B$3:$B$148,$B25,Checkliste!$E$3:$E$148,"offen") -> 5
B26: Safe Attachments (MDO) | C26: =COUNTIFS(Checkliste!$B$3:$B$148,$B26,Checkliste!$A$3:$A$148,"<>") -> 5 | D26: =COUNTIFS(Checkliste!$B$3:$B$148,$B26,Checkliste!$E$3:$E$148,"OK") -> 0 | E26: =COUNTIFS(Checkliste!$B$3:$B$148,$B26,Checkliste!$E$3:$E$148,"Verbesserung empfohlen") -> 0 | F26: =COUNTIFS(Checkliste!$B$3:$B$148,$B26,Checkliste!$E$3:$E$148,"Kritisch") -> 0 | G26: =COUNTIFS(Checkliste!$B$3:$B$148,$B26,Checkliste!$E$3:$E$148,"bewusst abgewichen") -> 0 | H26: =COUNTIFS(Checkliste!$B$3:$B$148,$B26,Checkliste!$E$3:$E$148,"n.a. (nicht lizenziert)") -> 0 | I26: =COUNTIFS(Checkliste!$B$3:$B$148,$B26,Checkliste!$E$3:$E$148,"offen") -> 5
B27: Safe Links (MDO) | C27: =COUNTIFS(Checkliste!$B$3:$B$148,$B27,Checkliste!$A$3:$A$148,"<>") -> 7 | D27: =COUNTIFS(Checkliste!$B$3:$B$148,$B27,Checkliste!$E$3:$E$148,"OK") -> 0 | E27: =COUNTIFS(Checkliste!$B$3:$B$148,$B27,Checkliste!$E$3:$E$148,"Verbesserung empfohlen") -> 0 | F27: =COUNTIFS(Checkliste!$B$3:$B$148,$B27,Checkliste!$E$3:$E$148,"Kritisch") -> 0 | G27: =COUNTIFS(Checkliste!$B$3:$B$148,$B27,Checkliste!$E$3:$E$148,"bewusst abgewichen") -> 0 | H27: =COUNTIFS(Checkliste!$B$3:$B$148,$B27,Checkliste!$E$3:$E$148,"n.a. (nicht lizenziert)") -> 0 | I27: =COUNTIFS(Checkliste!$B$3:$B$148,$B27,Checkliste!$E$3:$E$148,"offen") -> 7
B28: Quarantäne-Policies | C28: =COUNTIFS(Checkliste!$B$3:$B$148,$B28,Checkliste!$A$3:$A$148,"<>") -> 4 | D28: =COUNTIFS(Checkliste!$B$3:$B$148,$B28,Checkliste!$E$3:$E$148,"OK") -> 0 | E28: =COUNTIFS(Checkliste!$B$3:$B$148,$B28,Checkliste!$E$3:$E$148,"Verbesserung empfohlen") -> 0 | F28: =COUNTIFS(Checkliste!$B$3:$B$148,$B28,Checkliste!$E$3:$E$148,"Kritisch") -> 0 | G28: =COUNTIFS(Checkliste!$B$3:$B$148,$B28,Checkliste!$E$3:$E$148,"bewusst abgewichen") -> 0 | H28: =COUNTIFS(Checkliste!$B$3:$B$148,$B28,Checkliste!$E$3:$E$148,"n.a. (nicht lizenziert)") -> 0 | I28: =COUNTIFS(Checkliste!$B$3:$B$148,$B28,Checkliste!$E$3:$E$148,"offen") -> 4
... B39: Defender P2 (falls lizenziert) | C39: =COUNTIFS(Checkliste!$B$3:$B$148,$B39,Checkliste!$A$3:$A$148,"<>") -> 1 | D39: =COUNTIFS(Checkliste!$B$3:$B$148,$B39,Checkliste!$E$3:$E$148,"OK") -> 0 | E39: =COUNTIFS(Checkliste!$B$3:$B$148,$B39,Checkliste!$E$3:$E$148,"Verbesserung empfohlen") -> 0 | F39: =COUNTIFS(Checkliste!$B$3:$B$148,$B39,Checkliste!$E$3:$E$148,"Kritisch") -> 0 | G39: =COUNTIFS(Checkliste!$B$3:$B$148,$B39,Checkliste!$E$3:$E$148,"bewusst abgewichen") -> 0 | H39: =COUNTIFS(Checkliste!$B$3:$B$148,$B39,Checkliste!$E$3:$E$148,"n.a. (nicht lizenziert)") -> 0 | I39: =COUNTIFS(Checkliste!$B$3:$B$148,$B39,Checkliste!$E$3:$E$148,"offen") -> 1
B41: Kritische Punkte zuerst angehen
B42: Filtern Sie auf dem Blatt „Checkliste“ die Spalte „Bewertung“ nach „Kritisch“ — diese Punkte gehören in die Sofortmaßnahmen. Alles mit „Verbesserung empfohlen“ geht in die Folgeplanung.

Sheet Baseline (Skript)
A1: ID | B1: Kategorie | C1: Prüfpunkt | D1: Soll 2026 (Baseline)
A2: PRE-01 | B2: Preset Security Policies | C2: Grundsatzentscheidung: Preset (Standard/Strict) vs. Custom-Policies | D2: Bewusste, dokumentierte Entscheidung. Empfehlung 2026: Custom-Policies auf Standard-Preset-Niveau, wo Kontrolle nötig ist (ASF, Quarantäne-Policies, Länderfilter) — sonst Standard-Preset.
A3: PRE-02 | B3: Preset Security Policies | C3: Built-in protection Preset (Safe Links / Safe Attachments) aktiv, keine pauschalen Ausnahmen | D3: Aktiv, keine Ausnahmen für ganze Domänen
A4: PRE-03 | B4: Preset Security Policies | C4: Policy-Präzedenz dokumentiert und geprüft (welche Policy greift je Empfänger?) | D4: Kette dokumentiert: Strict > Standard > MDO-Evaluation > Custom (nach Priority) > Built-in + Default (gleichrangig)
A5: PRE-04 | B5: Preset Security Policies | C5: Configuration Analyzer ausgewertet (Standard- und Strict-Empfehlungen) | D5: Vor und nach dem Hardening ausgeführt, Abweichungen dokumentiert
A6: PRE-05 | B6: Preset Security Policies | C6: Policy-Inventar: verwaiste und deaktivierte Policies | D6: Jede Policy hat eine aktive Regel oder ist bewusst stillgelegt und dokumentiert
A7: ASI-01 | B7: Anti-Spam inbound | C7: Bulk-Schwellwert (BCL) | D7: 6
A8: ASI-02 | B8: Anti-Spam inbound | C8: Aktion bei Spam (SCL 5/6) | D8: MoveToJmf (Junk)
A9: ASI-03 | B9: Anti-Spam inbound | C9: Aktion bei High Confidence Spam (SCL 7/8/9) | D9: Quarantine + DefaultFullAccessWithNotificationPolicy (MS-konform) ODER AdminOnlyAccessPolicy (strengere Variante, bewusste Abweichung)
A10: ASI-04 | B10: Anti-Spam inbound | C10: Aktion bei Phishing | D10: Quarantine + DefaultFullAccessWithNotificationPolicy
A11: ASI-05 | B11: Anti-Spam inbound | C11: Aktion bei High Confidence Phishing | D11: Quarantine + AdminOnlyAccessPolicy
A12: ASI-06 | B12: Anti-Spam inbound | C12: Aktion bei Bulk (BCL-Schwelle erreicht) | D12: MoveToJmf
... A121: P2-01 | B121: Defender P2 (falls lizenziert) | C121: Automated Investigation and Response, Threat Explorer, Attack Simulation | D121: Ausstehende AIR-Aktionen regelmäßig freigeben; Threat Explorer und Campaign Views im Betrieb nutzen

Sheet Kürzel
B2: Was die Kürzel bedeuten
B4: Die ID ist über Checkliste, Guide, Audit-Skript und Hardening-Skript identisch. Das Präfix sagt, in welchem Bereich der Prüfpunkt sitzt — nicht zwingend, in welcher Portal-Richtlinie: APH und IMP stehen zum Beispiel beide in der Anti-Phishing-Richtlinie, sind aber lizenzrechtlich getrennt.
B7: Kürzel | C7: Bereich | D7: Was dahintersteckt
B8: PRE | C8: Preset Security Policies und Governance (5) | D8: Voreingestellte Sicherheitsrichtlinien, Praezedenz, Configuration Analyzer
B9: ASI | C9: Anti-Spam inbound (12) | D9: Anti-Spam-Richtlinie, eingehend
B10: ASF | C10: Advanced Spam Filter (5) | D10: Die ASF-Schalter innerhalb der Anti-Spam-Richtlinie
B11: CF | C11: Connection Filter (3) | D11: Verbindungsfilterrichtlinie - liegt als eigene Zeile in der Liste der Anti-Spam-Richtlinien
B12: ASO | C12: Anti-Spam outbound (8) | D12: Ausgehende Anti-Spam-Richtlinie plus Weiterleitungswege
B13: APH | C13: Anti-Phishing (EOP-Teil) (8) | D13: Spoof-Intelligence, DMARC-Behandlung, Sicherheitstipps - ohne Defender-Lizenz verfuegbar
B14: IMP | C14: Impersonation (Defender-Teil) (8) | D14: Identitaetswechselschutz - sitzt in derselben Anti-Phishing-Richtlinie, ist aber lizenzpflichtig
B15: TABL | C15: Tenant Allow/Block List (6) | D15: Mandanten-Zulassungs-/Sperrliste
B16: AMW | C16: Anti-Malware (5) | D16: Anti-Malware-Richtlinie und Anlagenfilter
B17: SA | C17: Safe Attachments (5) | D17: Sichere Anlagen (Defender)
B18: SL | C18: Safe Links (7) | D18: Sichere Links (Defender)
... B30: P2 | C30: Defender Plan 2 (1) | D30: Nur mit MDO P2: automatisierte Untersuchung (AIR)
B33: Zu den Links in der Checkliste
B34: Spalte „Fundort" beschreibt den Klickpfad, „Portal öffnen" springt direkt auf die Seite, „Microsoft Learn" auf den Abschnitt, der die Einstellung beschreibt. Der Pfad „Bedrohungsrichtlinien" liegt im Defender-Portal unter E-Mail & Zusammenarbeit > Richtlinien & Regeln. Sämtliche Defender-Deep-Links stammen aus der Microsoft-Dokumentation. Nicht von Microsoft dokumentiert und aus der Praxis übernommen sind die Exchange-Admin-Center-Links von ASO-07, ASO-08, HYB-06, HYB-07, HYB-10 — falls einer davon ins Leere führt, hilft der Klickpfad daneben.
